Workbook

Sheet 1. Datos brutos
A1: DATOS BRUTOS — Inflación anual (%) · 1993–2025 · Fuente: Variables_y_tipos_de_interes.xlsx
A2: Esta hoja contiene los valores numéricos originales. Todas las hojas siguientes referencian esta tabla con fórmulas.
A4: Código | B4: País | C4: Grupo | D4: 1993 | E4: 1994 | F4: 1995 | G4: 1996 | H4: 1997 | I4: 1998 | J4: 1999 | K4: 2000 | L4: 2001 | M4: 2002 | N4: 2003 | O4: 2004 | P4: 2005 | Q4: 2006 | R4: 2007 | S4: 2008 | T4: 2009 | U4: 2010 | V4: 2011 | W4: 2012 | X4: 2013 | Y4: 2014 | Z4: 2015 | AA4: 2016 | AB4: 2017 | AC4: 2018 | AD4: 2019 | AE4: 2020 | AF4: 2021 | AG4: 2022 | AH4: 2023 | AI4: 2024 | AJ4: 2025
A5: DEU | B5: Alemania | C5: Eurozona core | D5: 4.47 | E5: 2.69 | F5: 1.71 | G5: 1.45 | H5: 1.94 | I5: 0.91 | J5: 0.59 | K5: 1.44 | L5: 1.98 | M5: 1.42 | N5: 1.03 | O5: 1.67 | P5: 1.55 | Q5: 1.58 | R5: 2.3 | S5: 2.63 | T5: 0.31 | U5: 1.1 | V5: 2.08 | W5: 2.01 | X5: 1.5 | Y5: 0.91 | Z5: 0.51 | AA5: 0.49 | AB5: 1.51 | AC5: 1.73 | AD5: 1.45 | AE5: 0.14 | AF5: 3.07 | AG5: 6.87 | AH5: 5.95 | AI5: 2.26 | AJ5: 0
A6: AUT | B6: Austria | C6: Eurozona core | D6: 3.63 | E6: 2.95 | F6: 2.24 | G6: 1.86 | H6: 1.31 | I6: 0.92 | J6: 0.57 | K6: 2.34 | L6: 2.65 | M6: 1.81 | N6: 1.36 | O6: 2.06 | P6: 2.3 | Q6: 1.44 | R6: 2.17 | S6: 3.22 | T6: 0.51 | U6: 1.81 | V6: 3.29 | W6: 2.49 | X6: 2 | Y6: 1.61 | Z6: 0.9 | AA6: 0.89 | AB6: 2.08 | AC6: 2 | AD6: 1.53 | AE6: 1.38 | AF6: 2.77 | AG6: 8.55 | AH6: 7.81 | AI6: 2.94 | AJ6: 0
A7: BEL | B7: Bélgica | C7: Eurozona core | D7: 2.75 | E7: 2.38 | F7: 1.47 | G7: 2.08 | H7: 1.63 | I7: 0.95 | J7: 1.12 | K7: 2.54 | L7: 2.47 | M7: 1.65 | N7: 1.59 | O7: 2.1 | P7: 2.78 | Q7: 1.79 | R7: 1.82 | S7: 4.49 | T7: -0.05 | U7: 2.19 | V7: 3.53 | W7: 2.84 | X7: 1.11 | Y7: 0.34 | Z7: 0.56 | AA7: 1.97 | AB7: 2.13 | AC7: 2.05 | AD7: 1.44 | AE7: 0.74 | AF7: 2.44 | AG7: 9.6 | AH7: 4.05 | AI7: 3.14 | AJ7: 0
A8: CYP | B8: Chipre | C8: Eurozona core | D8: 4.85 | E8: 4.7 | F8: 2.62 | G8: 2.98 | H8: 3.61 | I8: 2.23 | J8: 1.63 | K8: 4.14 | L8: 1.97 | M8: 2.8 | N8: 4.14 | O8: 2.29 | P8: 2.56 | Q8: 2.3 | R8: 2.37 | S8: 4.67 | T8: 0.33 | U8: 2.43 | V8: 3.29 | W8: 2.39 | X8: -0.4 | Y8: -1.35 | Z8: -2.1 | AA8: -1.43 | AB8: 0.53 | AC8: 1.44 | AD8: 0.25 | AE8: -0.64 | AF8: 2.45 | AG8: 8.4 | AH8: 3.54 | AI8: 1.8 | AJ8: 0
A9: HRV | B9: Croacia | C9: Eurozona core | D9: 1500 | E9: 107.33 | F9: 3.95 | G9: 4.3 | H9: 4.17 | I9: 6.4 | J9: 4.02 | K9: 4.61 | L9: 3.78 | M9: 1.67 | N9: 1.77 | O9: 2.06 | P9: 3.32 | Q9: 3.19 | R9: 2.9 | S9: 6.08 | T9: 2.38 | U9: 1.03 | V9: 2.27 | W9: 3.41 | X9: 2.22 | Y9: -0.22 | Z9: -0.46 | AA9: -1.13 | AB9: 1.13 | AC9: 1.5 | AD9: 0.77 | AE9: 0.15 | AF9: 2.55 | AG9: 10.78 | AH9: 7.94 | AI9: 2.97 | AJ9: 0
A10: SVK | B10: Eslovaquia | C10: Eurozona core | D10: 23.29 | E10: 13.42 | F10: 9.84 | G10: 5.78 | H10: 6.14 | I10: 6.67 | J10: 10.57 | K10: 12.04 | L10: 7.33 | M10: 3.13 | N10: 8.55 | O10: 7.55 | P10: 2.71 | Q10: 4.48 | R10: 2.76 | S10: 4.6 | T10: 1.62 | U10: 0.96 | V10: 3.92 | W10: 3.61 | X10: 1.4 | Y10: -0.08 | Z10: -0.33 | AA10: -0.52 | AB10: 1.31 | AC10: 2.51 | AD10: 2.66 | AE10: 1.94 | AF10: 3.15 | AG10: 12.77 | AH10: 10.53 | AI10: 2.76 | AJ10: 0
A11: SVN | B11: Eslovenia | C11: Eurozona core | D11: 31.76 | E11: 20.99 | F11: 13.46 | G11: 9.86 | H11: 8.36 | I11: 7.89 | J11: 6.16 | K11: 8.91 | L11: 8.38 | M11: 7.48 | N11: 5.54 | O11: 3.59 | P11: 2.45 | Q11: 2.46 | R11: 3.66 | S11: 5.65 | T11: 0.84 | U11: 1.8 | V11: 1.8 | W11: 2.6 | X11: 1.77 | Y11: 0.2 | Z11: -0.53 | AA11: -0.05 | AB11: 1.43 | AC11: 1.74 | AD11: 1.63 | AE11: -0.05 | AF11: 1.92 | AG11: 8.83 | AH11: 7.45 | AI11: 1.97 | AJ11: 0
A12: ESP | B12: España | C12: Eurozona core | D12: 4.57 | E12: 4.72 | F12: 4.67 | G12: 3.56 | H12: 1.97 | I12: 1.83 | J12: 2.31 | K12: 3.43 | L12: 3.59 | M12: 3.07 | N12: 3.04 | O12: 3.04 | P12: 3.37 | Q12: 3.52 | R12: 2.79 | S12: 4.08 | T12: -0.29 | U12: 1.8 | V12: 3.2 | W12: 2.45 | X12: 1.41 | Y12: -0.15 | Z12: -0.5 | AA12: -0.2 | AB12: 1.96 | AC12: 1.67 | AD12: 0.7 | AE12: -0.32 | AF12: 3.09 | AG12: 8.39 | AH12: 3.53 | AI12: 2.77 | AJ12: 0
A13: EST | B13: Estonia | C13: Bálticos | D13: 89.81 | E13: 47.65 | F13: 28.78 | G13: 23.05 | H13: 10.58 | I13: 8.21 | J13: 3.3 | K13: 4.02 | L13: 5.75 | M13: 3.57 | N13: 1.33 | O13: 3.05 | P13: 4.08 | Q13: 4.44 | R13: 6.6 | S13: 10.36 | T13: -0.08 | U13: 2.97 | V13: 4.98 | W13: 3.93 | X13: 2.78 | Y13: -0.11 | Z13: -0.49 | AA13: 0.15 | AB13: 3.42 | AC13: 3.44 | AD13: 2.28 | AE13: -0.44 | AF13: 4.65 | AG13: 19.4 | AH13: 9.16 | AI13: 3.52 | AJ13: 0
A14: FIN | B14: Finlandia | C14: Eurozona core | D14: 2.19 | E14: 1.09 | F14: 0.79 | G14: 0.63 | H14: 1.19 | I14: 1.4 | J14: 1.16 | K14: 3.04 | L14: 2.58 | M14: 1.57 | N14: 0.88 | O14: 0.19 | P14: 0.62 | Q14: 1.57 | R14: 2.51 | S14: 4.07 | T14: 0 | U14: 1.18 | V14: 3.42 | W14: 2.81 | X14: 1.48 | Y14: 1.04 | Z14: -0.21 | AA14: 0.36 | AB14: 0.75 | AC14: 1.08 | AD14: 1.02 | AE14: 0.29 | AF14: 2.19 | AG14: 7.12 | AH14: 6.25 | AI14: 1.57 | AJ14: 0
A15: FRA | B15: Francia | C15: Eurozona core | D15: 2.1 | E15: 1.66 | F15: 1.8 | G15: 1.98 | H15: 1.2 | I15: 0.65 | J15: 0.54 | K15: 1.68 | L15: 1.63 | M15: 1.92 | N15: 2.1 | O15: 2.14 | P15: 1.75 | Q15: 1.68 | R15: 1.49 | S15: 2.81 | T15: 0.09 | U15: 1.53 | V15: 2.11 | W15: 1.95 | X15: 0.86 | Y15: 0.51 | Z15: 0.04 | AA15: 0.18 | AB15: 1.03 | AC15: 1.85 | AD15: 1.11 | AE15: 0.48 | AF15: 1.64 | AG15: 5.22 | AH15: 4.88 | AI15: 2 | AJ15: 0
A16: GRC | B16: Grecia | C16: Eurozona core | D16: 14.41 | E16: 10.87 | F16: 8.93 | G16: 8.19 | H16: 5.54 | I16: 4.77 | J16: 2.64 | K16: 3.15 | L16: 3.37 | M16: 3.63 | N16: 3.53 | O16: 2.9 | P16: 3.55 | Q16: 3.2 | R16: 2.9 | S16: 4.15 | T16: 1.21 | U16: 4.71 | V16: 3.33 | W16: 1.5 | X16: -0.92 | Y16: -1.31 | Z16: -1.74 | AA16: -0.83 | AB16: 1.12 | AC16: 0.63 | AD16: 0.25 | AE16: -1.25 | AF16: 1.22 | AG16: 9.65 | AH16: 3.46 | AI16: 2.74 | AJ16: 0
... A26: GBR | B26: Reino Unido | C26: Reino Unido | D26: 2.56 | E26: 2.22 | F26: 2.7 | G26: 2.85 | H26: 2.2 | I26: 1.82 | J26: 1.75 | K26: 1.18 | L26: 1.53 | M26: 1.52 | N26: 1.38 | O26: 1.39 | P26: 2.09 | Q26: 2.46 | R26: 2.39 | S26: 3.52 | T26: 1.96 | U26: 2.49 | V26: 3.86 | W26: 2.57 | X26: 2.29 | Y26: 1.45 | Z26: 0.37 | AA26: 1.01 | AB26: 2.56 | AC26: 2.29 | AD26: 1.74 | AE26: 0.99 | AF26: 2.52 | AG26: 7.92 | AH26: 6.79 | AI26: 3.27 | AJ26: 0

Sheet 2. Estadísticas descriptivas
A1: ESTADÍSTICAS DESCRIPTIVAS — Fórmulas referenciando '1. Datos brutos' · Azul=serie completa · Verde=serie limpia (≤30%)
A2: STDEV/PERCENTILE/MEDIAN sobre serie limpia usan fórmulas matriciales IF(). En Excel clásico confirmar con Ctrl+Shift+Enter.
A3: Identificación | D3: Serie completa | I3: Serie limpia (excl. >30%) | N3: Percentiles (limpia) | Q3: Frecuencias
A4: Código | B4: País | C4: Grupo | D4: Media completa | E4: Desv.típ. completa | F4: Mín. | G4: Año mín. | H4: Máx. | I4: Media limpia | J4: Desv.típ. limpia | K4: Mediana limpia | L4: CV limpia (%) | M4: IQR limpio | N4: P25 | O4: P75 | P4: N obs. | Q4: N extremos (>30%) | R4: N deflación (<0%)
A5: DEU | B5: Alemania | C5: Eurozona core | D5: =AVERAGE('1. Datos brutos'!$D$5:$AH$5) -> 1.9029032 | E5: =STDEV('1. Datos brutos'!$D$5:$AH$5) -> 1.4896022 | F5: =MIN('1. Datos brutos'!$D$5:$AH$5) -> 0.14 | G5: =INDEX('1. Datos brutos'!$D$4:$AH$4,MATCH(MIN('1. Datos brutos'!$D$5:$AH$5),'1. Datos brutos'!$D$5:$AH$5,0)) -> 2020 | H5: =MAX('1. Datos brutos'!$D$5:$AH$5) -> 6.87 | I5: =AVERAGEIF('1. Datos brutos'!$D$5:$AH$5,"<=30") -> 1.9029032 | J5: =STDEV(IF('1. Datos brutos'!$D$5:$AH$5<=30,'1. Datos brutos'!$D$5:$AH$5)) -> 1.4896022 | K5: =MEDIAN(IF('1. Datos brutos'!$D$5:$AH$5<=30,'1. Datos brutos'!$D$5:$AH$5)) -> 1.55 | L5: =IF(I5<>0,(J5/I5)*100,"") -> 78.280501 | M5: =PERCENTILE(IF('1. Datos brutos'!$D$5:$AH$5<=30,'1. Datos brutos'!$D$5:$AH$5),0.75)-PERCENTILE(IF('1. Datos brutos'!$D$5:$AH$5<=30,'1. Datos brutos'!$D$5:$AH$5),0.25) -> 0.98 | N5: =PERCENTILE(IF('1. Datos brutos'!$D$5:$AH$5<=30,'1. Datos brutos'!$D$5:$AH$5),0.25) -> 1.065 | O5: =PERCENTILE(IF('1. Datos brutos'!$D$5:$AH$5<=30,'1. Datos brutos'!$D$5:$AH$5),0.75) -> 2.045 | P5: =COUNT('1. Datos brutos'!$D$5:$AH$5) -> 31 | Q5: =COUNTIF('1. Datos brutos'!$D$5:$AH$5,">30") -> 0 | R5: =COUNTIF('1. Datos brutos'!$D$5:$AH$5,"<0") -> 0
A6: AUT | B6: Austria | C6: Eurozona core | D6: =AVERAGE('1. Datos brutos'!$D$6:$AH$6) -> 2.3370968 | E6: =STDEV('1. Datos brutos'!$D$6:$AH$6) -> 1.7447773 | F6: =MIN('1. Datos brutos'!$D$6:$AH$6) -> 0.51 | G6: =INDEX('1. Datos brutos'!$D$4:$AH$4,MATCH(MIN('1. Datos brutos'!$D$6:$AH$6),'1. Datos brutos'!$D$6:$AH$6,0)) -> 2009 | H6: =MAX('1. Datos brutos'!$D$6:$AH$6) -> 8.55 | I6: =AVERAGEIF('1. Datos brutos'!$D$6:$AH$6,"<=30") -> 2.3370968 | J6: =STDEV(IF('1. Datos brutos'!$D$6:$AH$6<=30,'1. Datos brutos'!$D$6:$AH$6)) -> 1.7447773 | K6: =MEDIAN(IF('1. Datos brutos'!$D$6:$AH$6<=30,'1. Datos brutos'!$D$6:$AH$6)) -> 2 | L6: =IF(I6<>0,(J6/I6)*100,"") -> 74.655759 | M6: =PERCENTILE(IF('1. Datos brutos'!$D$6:$AH$6<=30,'1. Datos brutos'!$D$6:$AH$6),0.75)-PERCENTILE(IF('1. Datos brutos'!$D$6:$AH$6<=30,'1. Datos brutos'!$D$6:$AH$6),0.25) -> 1.16 | N6: =PERCENTILE(IF('1. Datos brutos'!$D$6:$AH$6<=30,'1. Datos brutos'!$D$6:$AH$6),0.25) -> 1.41 | O6: =PERCENTILE(IF('1. Datos brutos'!$D$6:$AH$6<=30,'1. Datos brutos'!$D$6:$AH$6),0.75) -> 2.57 | P6: =COUNT('1. Datos brutos'!$D$6:$AH$6) -> 31 | Q6: =COUNTIF('1. Datos brutos'!$D$6:$AH$6,">30") -> 0 | R6: =COUNTIF('1. Datos brutos'!$D$6:$AH$6,"<0") -> 0
A7: BEL | B7: Bélgica | C7: Eurozona core | D7: =AVERAGE('1. Datos brutos'!$D$7:$AH$7) -> 2.2112903 | E7: =STDEV('1. Datos brutos'!$D$7:$AH$7) -> 1.6961343 | F7: =MIN('1. Datos brutos'!$D$7:$AH$7) -> -0.05 | G7: =INDEX('1. Datos brutos'!$D$4:$AH$4,MATCH(MIN('1. Datos brutos'!$D$7:$AH$7),'1. Datos brutos'!$D$7:$AH$7,0)) -> 2009 | H7: =MAX('1. Datos brutos'!$D$7:$AH$7) -> 9.6 | I7: =AVERAGEIF('1. Datos brutos'!$D$7:$AH$7,"<=30") -> 2.2112903 | J7: =STDEV(IF('1. Datos brutos'!$D$7:$AH$7<=30,'1. Datos brutos'!$D$7:$AH$7)) -> 1.6961343 | K7: =MEDIAN(IF('1. Datos brutos'!$D$7:$AH$7<=30,'1. Datos brutos'!$D$7:$AH$7)) -> 2.05 | L7: =IF(I7<>0,(J7/I7)*100,"") -> 76.703375 | M7: =PERCENTILE(IF('1. Datos brutos'!$D$7:$AH$7<=30,'1. Datos brutos'!$D$7:$AH$7),0.75)-PERCENTILE(IF('1. Datos brutos'!$D$7:$AH$7<=30,'1. Datos brutos'!$D$7:$AH$7),0.25) -> 1.05 | N7: =PERCENTILE(IF('1. Datos brutos'!$D$7:$AH$7<=30,'1. Datos brutos'!$D$7:$AH$7),0.25) -> 1.455 | O7: =PERCENTILE(IF('1. Datos brutos'!$D$7:$AH$7<=30,'1. Datos brutos'!$D$7:$AH$7),0.75) -> 2.505 | P7: =COUNT('1. Datos brutos'!$D$7:$AH$7) -> 31 | Q7: =COUNTIF('1. Datos brutos'!$D$7:$AH$7,">30") -> 0 | R7: =COUNTIF('1. Datos brutos'!$D$7:$AH$7,"<0") -> 1
A8: CYP | B8: Chipre | C8: Eurozona core | D8: =AVERAGE('1. Datos brutos'!$D$8:$AH$8) -> 2.2254839 | E8: =STDEV('1. Datos brutos'!$D$8:$AH$8) -> 2.1748929 | F8: =MIN('1. Datos brutos'!$D$8:$AH$8) -> -2.1 | G8: =INDEX('1. Datos brutos'!$D$4:$AH$4,MATCH(MIN('1. Datos brutos'!$D$8:$AH$8),'1. Datos brutos'!$D$8:$AH$8,0)) -> 2015 | H8: =MAX('1. Datos brutos'!$D$8:$AH$8) -> 8.4 | I8: =AVERAGEIF('1. Datos brutos'!$D$8:$AH$8,"<=30") -> 2.2254839 | J8: =STDEV(IF('1. Datos brutos'!$D$8:$AH$8<=30,'1. Datos brutos'!$D$8:$AH$8)) -> 2.1748929 | K8: =MEDIAN(IF('1. Datos brutos'!$D$8:$AH$8<=30,'1. Datos brutos'!$D$8:$AH$8)) -> 2.39 | L8: =IF(I8<>0,(J8/I8)*100,"") -> 97.726741 | M8: =PERCENTILE(IF('1. Datos brutos'!$D$8:$AH$8<=30,'1. Datos brutos'!$D$8:$AH$8),0.75)-PERCENTILE(IF('1. Datos brutos'!$D$8:$AH$8<=30,'1. Datos brutos'!$D$8:$AH$8),0.25) -> 2.43 | N8: =PERCENTILE(IF('1. Datos brutos'!$D$8:$AH$8<=30,'1. Datos brutos'!$D$8:$AH$8),0.25) -> 0.985 | O8: =PERCENTILE(IF('1. Datos brutos'!$D$8:$AH$8<=30,'1. Datos brutos'!$D$8:$AH$8),0.75) -> 3.415 | P8: =COUNT('1. Datos brutos'!$D$8:$AH$8) -> 31 | Q8: =COUNTIF('1. Datos brutos'!$D$8:$AH$8,">30") -> 0 | R8: =COUNTIF('1. Datos brutos'!$D$8:$AH$8,"<0") -> 5
A9: HRV | B9: Croacia | C9: Eurozona core | D9: =AVERAGE('1. Datos brutos'!$D$9:$AH$9) -> 54.640968 | E9: =STDEV('1. Datos brutos'!$D$9:$AH$9) -> 268.91174 | F9: =MIN('1. Datos brutos'!$D$9:$AH$9) -> -1.13 | G9: =INDEX('1. Datos brutos'!$D$4:$AH$4,MATCH(MIN('1. Datos brutos'!$D$9:$AH$9),'1. Datos brutos'!$D$9:$AH$9,0)) -> 2016 | H9: =MAX('1. Datos brutos'!$D$9:$AH$9) -> 1500 | I9: =AVERAGEIF('1. Datos brutos'!$D$9:$AH$9,"<=30") -> 2.9841379 | J9: =STDEV(IF('1. Datos brutos'!$D$9:$AH$9<=30,'1. Datos brutos'!$D$9:$AH$9)) -> 268.91174 | K9: =MEDIAN(IF('1. Datos brutos'!$D$9:$AH$9<=30,'1. Datos brutos'!$D$9:$AH$9)) -> 2.9 | L9: =IF(I9<>0,(J9/I9)*100,"") -> 9011.3711 | M9: =PERCENTILE(IF('1. Datos brutos'!$D$9:$AH$9<=30,'1. Datos brutos'!$D$9:$AH$9),0.75)-PERCENTILE(IF('1. Datos brutos'!$D$9:$AH$9<=30,'1. Datos brutos'!$D$9:$AH$9),0.25) -> 2.65 | N9: =PERCENTILE(IF('1. Datos brutos'!$D$9:$AH$9<=30,'1. Datos brutos'!$D$9:$AH$9),0.25) -> 1.585 | O9: =PERCENTILE(IF('1. Datos brutos'!$D$9:$AH$9<=30,'1. Datos brutos'!$D$9:$AH$9),0.75) -> 4.235 | P9: =COUNT('1. Datos brutos'!$D$9:$AH$9) -> 31 | Q9: =COUNTIF('1. Datos brutos'!$D$9:$AH$9,">30") -> 2 | R9: =COUNTIF('1. Datos brutos'!$D$9:$AH$9,"<0") -> 3
A10: SVK | B10: Eslovaquia | C10: Eurozona core | D10: =AVERAGE('1. Datos brutos'!$D$10:$AH$10) -> 5.6229032 | E10: =STDEV('1. Datos brutos'!$D$10:$AH$10) -> 5.1586369 | F10: =MIN('1. Datos brutos'!$D$10:$AH$10) -> -0.52 | G10: =INDEX('1. Datos brutos'!$D$4:$AH$4,MATCH(MIN('1. Datos brutos'!$D$10:$AH$10),'1. Datos brutos'!$D$10:$AH$10,0)) -> 2016 | H10: =MAX('1. Datos brutos'!$D$10:$AH$10) -> 23.29 | I10: =AVERAGEIF('1. Datos brutos'!$D$10:$AH$10,"<=30") -> 5.6229032 | J10: =STDEV(IF('1. Datos brutos'!$D$10:$AH$10<=30,'1. Datos brutos'!$D$10:$AH$10)) -> 5.1586369 | K10: =MEDIAN(IF('1. Datos brutos'!$D$10:$AH$10<=30,'1. Datos brutos'!$D$10:$AH$10)) -> 3.92 | L10: =IF(I10<>0,(J10/I10)*100,"") -> 91.743299 | M10: =PERCENTILE(IF('1. Datos brutos'!$D$10:$AH$10<=30,'1. Datos brutos'!$D$10:$AH$10),0.75)-PERCENTILE(IF('1. Datos brutos'!$D$10:$AH$10<=30,'1. Datos brutos'!$D$10:$AH$10),0.25) -> 5.825 | N10: =PERCENTILE(IF('1. Datos brutos'!$D$10:$AH$10<=30,'1. Datos brutos'!$D$10:$AH$10),0.25) -> 2.225 | O10: =PERCENTILE(IF('1. Datos brutos'!$D$10:$AH$10<=30,'1. Datos brutos'!$D$10:$AH$10),0.75) -> 8.05 | P10: =COUNT('1. Datos brutos'!$D$10:$AH$10) -> 31 | Q10: =COUNTIF('1. Datos brutos'!$D$10:$AH$10,">30") -> 0 | R10: =COUNTIF('1. Datos brutos'!$D$10:$AH$10,"<0") -> 3
A11: SVN | B11: Eslovenia | C11: Eurozona core | D11: =AVERAGE('1. Datos brutos'!$D$11:$AH$11) -> 5.7412903 | E11: =STDEV('1. Datos brutos'!$D$11:$AH$11) -> 6.6950921 | F11: =MIN('1. Datos brutos'!$D$11:$AH$11) -> -0.53 | G11: =INDEX('1. Datos brutos'!$D$4:$AH$4,MATCH(MIN('1. Datos brutos'!$D$11:$AH$11),'1. Datos brutos'!$D$11:$AH$11,0)) -> 2015 | H11: =MAX('1. Datos brutos'!$D$11:$AH$11) -> 31.76 | I11: =AVERAGEIF('1. Datos brutos'!$D$11:$AH$11,"<=30") -> 4.874 | J11: =STDEV(IF('1. Datos brutos'!$D$11:$AH$11<=30,'1. Datos brutos'!$D$11:$AH$11)) -> 6.6950921 | K11: =MEDIAN(IF('1. Datos brutos'!$D$11:$AH$11<=30,'1. Datos brutos'!$D$11:$AH$11)) -> 3.59 | L11: =IF(I11<>0,(J11/I11)*100,"") -> 137.3634 | M11: =PERCENTILE(IF('1. Datos brutos'!$D$11:$AH$11<=30,'1. Datos brutos'!$D$11:$AH$11),0.75)-PERCENTILE(IF('1. Datos brutos'!$D$11:$AH$11<=30,'1. Datos brutos'!$D$11:$AH$11),0.25) -> 6.37 | N11: =PERCENTILE(IF('1. Datos brutos'!$D$11:$AH$11<=30,'1. Datos brutos'!$D$11:$AH$11),0.25) -> 1.755 | O11: =PERCENTILE(IF('1. Datos brutos'!$D$11:$AH$11<=30,'1. Datos brutos'!$D$11:$AH$11),0.75) -> 8.125 | P11: =COUNT('1. Datos brutos'!$D$11:$AH$11) -> 31 | Q11: =COUNTIF('1. Datos brutos'!$D$11:$AH$11,">30") -> 1 | R11: =COUNTIF('1. Datos brutos'!$D$11:$AH$11,"<0") -> 3
A12: ESP | B12: España | C12: Eurozona core | D12: =AVERAGE('1. Datos brutos'!$D$12:$AH$12) -> 2.5903226 | E12: =STDEV('1. Datos brutos'!$D$12:$AH$12) -> 1.8658233 | F12: =MIN('1. Datos brutos'!$D$12:$AH$12) -> -0.5 | G12: =INDEX('1. Datos brutos'!$D$4:$AH$4,MATCH(MIN('1. Datos brutos'!$D$12:$AH$12),'1. Datos brutos'!$D$12:$AH$12,0)) -> 2015 | H12: =MAX('1. Datos brutos'!$D$12:$AH$12) -> 8.39 | I12: =AVERAGEIF('1. Datos brutos'!$D$12:$AH$12,"<=30") -> 2.5903226 | J12: =STDEV(IF('1. Datos brutos'!$D$12:$AH$12<=30,'1. Datos brutos'!$D$12:$AH$12)) -> 1.8658233 | K12: =MEDIAN(IF('1. Datos brutos'!$D$12:$AH$12<=30,'1. Datos brutos'!$D$12:$AH$12)) -> 3.04 | L12: =IF(I12<>0,(J12/I12)*100,"") -> 72.030538 | M12: =PERCENTILE(IF('1. Datos brutos'!$D$12:$AH$12<=30,'1. Datos brutos'!$D$12:$AH$12),0.75)-PERCENTILE(IF('1. Datos brutos'!$D$12:$AH$12<=30,'1. Datos brutos'!$D$12:$AH$12),0.25) -> 1.79 | N12: =PERCENTILE(IF('1. Datos brutos'!$D$12:$AH$12<=30,'1. Datos brutos'!$D$12:$AH$12),0.25) -> 1.735 | O12: =PERCENTILE(IF('1. Datos brutos'!$D$12:$AH$12<=30,'1. Datos brutos'!$D$12:$AH$12),0.75) -> 3.525 | P12: =COUNT('1. Datos brutos'!$D$12:$AH$12) -> 31 | Q12: =COUNTIF('1. Datos brutos'!$D$12:$AH$12,">30") -> 0 | R12: =COUNTIF('1. Datos brutos'!$D$12:$AH$12,"<0") -> 5
A13: EST | B13: Estonia | C13: Bálticos | D13: =AVERAGE('1. Datos brutos'!$D$13:$AH$13) -> 10.02 | E13: =STDEV('1. Datos brutos'!$D$13:$AH$13) -> 17.890353 | F13: =MIN('1. Datos brutos'!$D$13:$AH$13) -> -0.49 | G13: =INDEX('1. Datos brutos'!$D$4:$AH$4,MATCH(MIN('1. Datos brutos'!$D$13:$AH$13),'1. Datos brutos'!$D$13:$AH$13,0)) -> 2015 | H13: =MAX('1. Datos brutos'!$D$13:$AH$13) -> 89.81 | I13: =AVERAGEIF('1. Datos brutos'!$D$13:$AH$13,"<=30") -> 5.9710345 | J13: =STDEV(IF('1. Datos brutos'!$D$13:$AH$13<=30,'1. Datos brutos'!$D$13:$AH$13)) -> 17.890353 | K13: =MEDIAN(IF('1. Datos brutos'!$D$13:$AH$13<=30,'1. Datos brutos'!$D$13:$AH$13)) -> 4.02 | L13: =IF(I13<>0,(J13/I13)*100,"") -> 299.61899 | M13: =PERCENTILE(IF('1. Datos brutos'!$D$13:$AH$13<=30,'1. Datos brutos'!$D$13:$AH$13),0.75)-PERCENTILE(IF('1. Datos brutos'!$D$13:$AH$13<=30,'1. Datos brutos'!$D$13:$AH$13),0.25) -> 5.81 | N13: =PERCENTILE(IF('1. Datos brutos'!$D$13:$AH$13<=30,'1. Datos brutos'!$D$13:$AH$13),0.25) -> 2.875 | O13: =PERCENTILE(IF('1. Datos brutos'!$D$13:$AH$13<=30,'1. Datos brutos'!$D$13:$AH$13),0.75) -> 8.685 | P13: =COUNT('1. Datos brutos'!$D$13:$AH$13) -> 31 | Q13: =COUNTIF('1. Datos brutos'!$D$13:$AH$13,">30") -> 2 | R13: =COUNTIF('1. Datos brutos'!$D$13:$AH$13,"<0") -> 4
A14: FIN | B14: Finlandia | C14: Eurozona core | D14: =AVERAGE('1. Datos brutos'!$D$14:$AH$14) -> 1.7503226 | E14: =STDEV('1. Datos brutos'!$D$14:$AH$14) -> 1.6681237 | F14: =MIN('1. Datos brutos'!$D$14:$AH$14) -> -0.21 | G14: =INDEX('1. Datos brutos'!$D$4:$AH$4,MATCH(MIN('1. Datos brutos'!$D$14:$AH$14),'1. Datos brutos'!$D$14:$AH$14,0)) -> 2015 | H14: =MAX('1. Datos brutos'!$D$14:$AH$14) -> 7.12 | I14: =AVERAGEIF('1. Datos brutos'!$D$14:$AH$14,"<=30") -> 1.7503226 | J14: =STDEV(IF('1. Datos brutos'!$D$14:$AH$14<=30,'1. Datos brutos'!$D$14:$AH$14)) -> 1.6681237 | K14: =MEDIAN(IF('1. Datos brutos'!$D$14:$AH$14<=30,'1. Datos brutos'!$D$14:$AH$14)) -> 1.18 | L14: =IF(I14<>0,(J14/I14)*100,"") -> 95.303785 | M14: =PERCENTILE(IF('1. Datos brutos'!$D$14:$AH$14<=30,'1. Datos brutos'!$D$14:$AH$14),0.75)-PERCENTILE(IF('1. Datos brutos'!$D$14:$AH$14<=30,'1. Datos brutos'!$D$14:$AH$14),0.25) -> 1.58 | N14: =PERCENTILE(IF('1. Datos brutos'!$D$14:$AH$14<=30,'1. Datos brutos'!$D$14:$AH$14),0.25) -> 0.77 | O14: =PERCENTILE(IF('1. Datos brutos'!$D$14:$AH$14<=30,'1. Datos brutos'!$D$14:$AH$14),0.75) -> 2.35 | P14: =COUNT('1. Datos brutos'!$D$14:$AH$14) -> 31 | Q14: =COUNTIF('1. Datos brutos'!$D$14:$AH$14,">30") -> 0 | R14: =COUNTIF('1. Datos brutos'!$D$14:$AH$14,"<0") -> 1
A15: FRA | B15: Francia | C15: Eurozona core | D15: =AVERAGE('1. Datos brutos'!$D$15:$AH$15) -> 1.6325806 | E15: =STDEV('1. Datos brutos'!$D$15:$AH$15) -> 1.1452393 | F15: =MIN('1. Datos brutos'!$D$15:$AH$15) -> 0.04 | G15: =INDEX('1. Datos brutos'!$D$4:$AH$4,MATCH(MIN('1. Datos brutos'!$D$15:$AH$15),'1. Datos brutos'!$D$15:$AH$15,0)) -> 2015 | H15: =MAX('1. Datos brutos'!$D$15:$AH$15) -> 5.22 | I15: =AVERAGEIF('1. Datos brutos'!$D$15:$AH$15,"<=30") -> 1.6325806 | J15: =STDEV(IF('1. Datos brutos'!$D$15:$AH$15<=30,'1. Datos brutos'!$D$15:$AH$15)) -> 1.1452393 | K15: =MEDIAN(IF('1. Datos brutos'!$D$15:$AH$15<=30,'1. Datos brutos'!$D$15:$AH$15)) -> 1.66 | L15: =IF(I15<>0,(J15/I15)*100,"") -> 70.14902 | M15: =PERCENTILE(IF('1. Datos brutos'!$D$15:$AH$15<=30,'1. Datos brutos'!$D$15:$AH$15),0.75)-PERCENTILE(IF('1. Datos brutos'!$D$15:$AH$15<=30,'1. Datos brutos'!$D$15:$AH$15),0.25) -> 1.02 | N15: =PERCENTILE(IF('1. Datos brutos'!$D$15:$AH$15<=30,'1. Datos brutos'!$D$15:$AH$15),0.25) -> 0.945 | O15: =PERCENTILE(IF('1. Datos brutos'!$D$15:$AH$15<=30,'1. Datos brutos'!$D$15:$AH$15),0.75) -> 1.965 | P15: =COUNT('1. Datos brutos'!$D$15:$AH$15) -> 31 | Q15: =COUNTIF('1. Datos brutos'!$D$15:$AH$15,">30") -> 0 | R15: =COUNTIF('1. Datos brutos'!$D$15:$AH$15,"<0") -> 0
A16: GRC | B16: Grecia | C16: Eurozona core | D16: =AVERAGE('1. Datos brutos'!$D$16:$AH$16) -> 3.443871 | E16: =STDEV('1. Datos brutos'!$D$16:$AH$16) -> 3.7518863 | F16: =MIN('1. Datos brutos'!$D$16:$AH$16) -> -1.74 | G16: =INDEX('1. Datos brutos'!$D$4:$AH$4,MATCH(MIN('1. Datos brutos'!$D$16:$AH$16),'1. Datos brutos'!$D$16:$AH$16,0)) -> 2015 | H16: =MAX('1. Datos brutos'!$D$16:$AH$16) -> 14.41 | I16: =AVERAGEIF('1. Datos brutos'!$D$16:$AH$16,"<=30") -> 3.443871 | J16: =STDEV(IF('1. Datos brutos'!$D$16:$AH$16<=30,'1. Datos brutos'!$D$16:$AH$16)) -> 3.7518863 | K16: =MEDIAN(IF('1. Datos brutos'!$D$16:$AH$16<=30,'1. Datos brutos'!$D$16:$AH$16)) -> 3.2 | L16: =IF(I16<>0,(J16/I16)*100,"") -> 108.94387 | M16: =PERCENTILE(IF('1. Datos brutos'!$D$16:$AH$16<=30,'1. Datos brutos'!$D$16:$AH$16),0.75)-PERCENTILE(IF('1. Datos brutos'!$D$16:$AH$16<=30,'1. Datos brutos'!$D$16:$AH$16),0.25) -> 3.265 | N16: =PERCENTILE(IF('1. Datos brutos'!$D$16:$AH$16<=30,'1. Datos brutos'!$D$16:$AH$16),0.25) -> 1.165 | O16: =PERCENTILE(IF('1. Datos brutos'!$D$16:$AH$16<=30,'1. Datos brutos'!$D$16:$AH$16),0.75) -> 4.43 | P16: =COUNT('1. Datos brutos'!$D$16:$AH$16) -> 31 | Q16: =COUNTIF('1. Datos brutos'!$D$16:$AH$16,">30") -> 0 | R16: =COUNTIF('1. Datos brutos'!$D$16:$AH$16,"<0") -> 5
A17: IRL | B17: Irlanda | C17: Eurozona core | D17: =AVERAGE('1. Datos brutos'!$D$17:$AH$17) -> 2.1574194 | E17: =STDEV('1. Datos brutos'!$D$17:$AH$17) -> 2.4260489 | F17: =MIN('1. Datos brutos'!$D$17:$AH$17) -> -4.45 | G17: =INDEX('1. Datos brutos'!$D$4:$AH$4,MATCH(MIN('1. Datos brutos'!$D$17:$AH$17),'1. Datos brutos'!$D$17:$AH$17,0)) -> 2009 | H17: =MAX('1. Datos brutos'!$D$17:$AH$17) -> 7.83 | I17: =AVERAGEIF('1. Datos brutos'!$D$17:$AH$17,"<=30") -> 2.1574194 | J17: =STDEV(IF('1. Datos brutos'!$D$17:$AH$17<=30,'1. Datos brutos'!$D$17:$AH$17)) -> 2.4260489 | K17: =MEDIAN(IF('1. Datos brutos'!$D$17:$AH$17<=30,'1. Datos brutos'!$D$17:$AH$17)) -> 2.18 | L17: =IF(I17<>0,(J17/I17)*100,"") -> 112.45143 | M17: =PERCENTILE(IF('1. Datos brutos'!$D$17:$AH$17<=30,'1. Datos brutos'!$D$17:$AH$17),0.75)-PERCENTILE(IF('1. Datos brutos'!$D$17:$AH$17<=30,'1. Datos brutos'!$D$17:$AH$17),0.25) -> 3.22 | N17: =PERCENTILE(IF('1. Datos brutos'!$D$17:$AH$17<=30,'1. Datos brutos'!$D$17:$AH$17),0.25) -> 0.495 | O17: =PERCENTILE(IF('1. Datos brutos'!$D$17:$AH$17<=30,'1. Datos brutos'!$D$17:$AH$17),0.75) -> 3.715 | P17: =COUNT('1. Datos brutos'!$D$17:$AH$17) -> 31 | Q17: =COUNTIF('1. Datos brutos'!$D$17:$AH$17,">30") -> 0 | R17: =COUNTIF('1. Datos brutos'!$D$17:$AH$17,"<0") -> 4
A18: ITA | B18: Italia | C18: Eurozona core | D18: =AVERAGE('1. Datos brutos'!$D$18:$AH$18) -> 2.373871 | E18: =STDEV('1. Datos brutos'!$D$18:$AH$18) -> 1.8227903 | F18: =MIN('1. Datos brutos'!$D$18:$AH$18) -> -0.14 | G18: =INDEX('1. Datos brutos'!$D$4:$AH$4,MATCH(MIN('1. Datos brutos'!$D$18:$AH$18),'1. Datos brutos'!$D$18:$AH$18,0)) -> 2020 | H18: =MAX('1. Datos brutos'!$D$18:$AH$18) -> 8.2 | I18: =AVERAGEIF('1. Datos brutos'!$D$18:$AH$18,"<=30") -> 2.373871 | J18: =STDEV(IF('1. Datos brutos'!$D$18:$AH$18<=30,'1. Datos brutos'!$D$18:$AH$18)) -> 1.8227903 | K18: =MEDIAN(IF('1. Datos brutos'!$D$18:$AH$18<=30,'1. Datos brutos'!$D$18:$AH$18)) -> 2.04 | L18: =IF(I18<>0,(J18/I18)*100,"") -> 76.785568 | M18: =PERCENTILE(IF('1. Datos brutos'!$D$18:$AH$18<=30,'1. Datos brutos'!$D$18:$AH$18),0.75)-PERCENTILE(IF('1. Datos brutos'!$D$18:$AH$18<=30,'1. Datos brutos'!$D$18:$AH$18),0.25) -> 1.69 | N18: =PERCENTILE(IF('1. Datos brutos'!$D$18:$AH$18<=30,'1. Datos brutos'!$D$18:$AH$18),0.25) -> 1.225 | O18: =PERCENTILE(IF('1. Datos brutos'!$D$18:$AH$18<=30,'1. Datos brutos'!$D$18:$AH$18),0.75) -> 2.915 | P18: =COUNT('1. Datos brutos'!$D$18:$AH$18) -> 31 | Q18: =COUNTIF('1. Datos brutos'!$D$18:$AH$18,">30") -> 0 | R18: =COUNTIF('1. Datos brutos'!$D$18:$AH$18,"<0") -> 2
A19: LVA | B19: Letonia | C19: Bálticos | D19: =AVERAGE('1. Datos brutos'!$D$19:$AH$19) -> 9.8690323 | E19: =STDEV('1. Datos brutos'!$D$19:$AH$19) -> 20.103989 | F19: =MIN('1. Datos brutos'!$D$19:$AH$19) -> -1.08 | G19: =INDEX('1. Datos brutos'!$D$4:$AH$4,MATCH(MIN('1. Datos brutos'!$D$19:$AH$19),'1. Datos brutos'!$D$19:$AH$19,0)) -> 2010 | H19: =MAX('1. Datos brutos'!$D$19:$AH$19) -> 108.99 | I19: =AVERAGEIF('1. Datos brutos'!$D$19:$AH$19,"<=30") -> 5.5527586 | J19: =STDEV(IF('1. Datos brutos'!$D$19:$AH$19<=30,'1. Datos brutos'!$D$19:$AH$19)) -> 20.103989 | K19: =MEDIAN(IF('1. Datos brutos'!$D$19:$AH$19<=30,'1. Datos brutos'!$D$19:$AH$19)) -> 3.28 | L19: =IF(I19<>0,(J19/I19)*100,"") -> 362.05408 | M19: =PERCENTILE(IF('1. Datos brutos'!$D$19:$AH$19<=30,'1. Datos brutos'!$D$19:$AH$19),0.75)-PERCENTILE(IF('1. Datos brutos'!$D$19:$AH$19<=30,'1. Datos brutos'!$D$19:$AH$19),0.25) -> 6.385 | N19: =PERCENTILE(IF('1. Datos brutos'!$D$19:$AH$19<=30,'1. Datos brutos'!$D$19:$AH$19),0.25) -> 2.31 | O19: =PERCENTILE(IF('1. Datos brutos'!$D$19:$AH$19<=30,'1. Datos brutos'!$D$19:$AH$19),0.75) -> 8.695 | P19: =COUNT('1. Datos brutos'!$D$19:$AH$19) -> 31 | Q19: =COUNTIF('1. Datos brutos'!$D$19:$AH$19,">30") -> 2 | R19: =COUNTIF('1. Datos brutos'!$D$19:$AH$19,"<0") -> 2
A20: LTU | B20: Lituania | C20: Bálticos | D20: =AVERAGE('1. Datos brutos'!$D$20:$AH$20) -> 20.807097 | E20: =STDEV('1. Datos brutos'!$D$20:$AH$20) -> 73.779753 | F20: =MIN('1. Datos brutos'!$D$20:$AH$20) -> -1.13 | G20: =INDEX('1. Datos brutos'!$D$4:$AH$4,MATCH(MIN('1. Datos brutos'!$D$20:$AH$20),'1. Datos brutos'!$D$20:$AH$20,0)) -> 2003 | H20: =MAX('1. Datos brutos'!$D$20:$AH$20) -> 410.45 | I20: =AVERAGEIF('1. Datos brutos'!$D$20:$AH$20,"<=30") -> 4.3810714 | J20: =STDEV(IF('1. Datos brutos'!$D$20:$AH$20<=30,'1. Datos brutos'!$D$20:$AH$20)) -> 73.779753 | K20: =MEDIAN(IF('1. Datos brutos'!$D$20:$AH$20<=30,'1. Datos brutos'!$D$20:$AH$20)) -> 3.09 | L20: =IF(I20<>0,(J20/I20)*100,"") -> 1684.0573 | M20: =PERCENTILE(IF('1. Datos brutos'!$D$20:$AH$20<=30,'1. Datos brutos'!$D$20:$AH$20),0.75)-PERCENTILE(IF('1. Datos brutos'!$D$20:$AH$20<=30,'1. Datos brutos'!$D$20:$AH$20),0.25) -> 6.205 | N20: =PERCENTILE(IF('1. Datos brutos'!$D$20:$AH$20<=30,'1. Datos brutos'!$D$20:$AH$20),0.25) -> 1.105 | O20: =PERCENTILE(IF('1. Datos brutos'!$D$20:$AH$20<=30,'1. Datos brutos'!$D$20:$AH$20),0.75) -> 7.31 | P20: =COUNT('1. Datos brutos'!$D$20:$AH$20) -> 31 | Q20: =COUNTIF('1. Datos brutos'!$D$20:$AH$20,">30") -> 3 | R20: =COUNTIF('1. Datos brutos'!$D$20:$AH$20,"<0") -> 2
A21: LUX | B21: Luxemburgo | C21: Eurozona core | D21: =AVERAGE('1. Datos brutos'!$D$21:$AH$21) -> 2.1122581 | E21: =STDEV('1. Datos brutos'!$D$21:$AH$21) -> 1.2397841 | F21: =MIN('1. Datos brutos'!$D$21:$AH$21) -> 0.29 | G21: =INDEX('1. Datos brutos'!$D$4:$AH$4,MATCH(MIN('1. Datos brutos'!$D$21:$AH$21),'1. Datos brutos'!$D$21:$AH$21,0)) -> 2016 | H21: =MAX('1. Datos brutos'!$D$21:$AH$21) -> 6.34 | I21: =AVERAGEIF('1. Datos brutos'!$D$21:$AH$21,"<=30") -> 2.1122581 | J21: =STDEV(IF('1. Datos brutos'!$D$21:$AH$21<=30,'1. Datos brutos'!$D$21:$AH$21)) -> 1.2397841 | K21: =MEDIAN(IF('1. Datos brutos'!$D$21:$AH$21<=30,'1. Datos brutos'!$D$21:$AH$21)) -> 2.07 | L21: =IF(I21<>0,(J21/I21)*100,"") -> 58.694729 | M21: =PERCENTILE(IF('1. Datos brutos'!$D$21:$AH$21<=30,'1. Datos brutos'!$D$21:$AH$21),0.75)-PERCENTILE(IF('1. Datos brutos'!$D$21:$AH$21<=30,'1. Datos brutos'!$D$21:$AH$21),0.25) -> 1.385 | N21: =PERCENTILE(IF('1. Datos brutos'!$D$21:$AH$21<=30,'1. Datos brutos'!$D$21:$AH$21),0.25) -> 1.275 | O21: =PERCENTILE(IF('1. Datos brutos'!$D$21:$AH$21<=30,'1. Datos brutos'!$D$21:$AH$21),0.75) -> 2.66 | P21: =COUNT('1. Datos brutos'!$D$21:$AH$21) -> 31 | Q21: =COUNTIF('1. Datos brutos'!$D$21:$AH$21,">30") -> 0 | R21: =COUNTIF('1. Datos brutos'!$D$21:$AH$21,"<0") -> 0
A22: MLT | B22: Malta | C22: Eurozona core | D22: =AVERAGE('1. Datos brutos'!$D$22:$AH$22) -> 2.4180645 | E22: =STDEV('1. Datos brutos'!$D$22:$AH$22) -> 1.3910174 | F22: =MIN('1. Datos brutos'!$D$22:$AH$22) -> 0.31 | G22: =INDEX('1. Datos brutos'!$D$4:$AH$4,MATCH(MIN('1. Datos brutos'!$D$22:$AH$22),'1. Datos brutos'!$D$22:$AH$22,0)) -> 2014 | H22: =MAX('1. Datos brutos'!$D$22:$AH$22) -> 6.15 | I22: =AVERAGEIF('1. Datos brutos'!$D$22:$AH$22,"<=30") -> 2.4180645 | J22: =STDEV(IF('1. Datos brutos'!$D$22:$AH$22<=30,'1. Datos brutos'!$D$22:$AH$22)) -> 1.3910174 | K22: =MEDIAN(IF('1. Datos brutos'!$D$22:$AH$22<=30,'1. Datos brutos'!$D$22:$AH$22)) -> 2.19 | L22: =IF(I22<>0,(J22/I22)*100,"") -> 57.526067 | M22: =PERCENTILE(IF('1. Datos brutos'!$D$22:$AH$22<=30,'1. Datos brutos'!$D$22:$AH$22),0.75)-PERCENTILE(IF('1. Datos brutos'!$D$22:$AH$22<=30,'1. Datos brutos'!$D$22:$AH$22),0.25) -> 1.655 | N22: =PERCENTILE(IF('1. Datos brutos'!$D$22:$AH$22<=30,'1. Datos brutos'!$D$22:$AH$22),0.25) -> 1.33 | O22: =PERCENTILE(IF('1. Datos brutos'!$D$22:$AH$22<=30,'1. Datos brutos'!$D$22:$AH$22),0.75) -> 2.985 | P22: =COUNT('1. Datos brutos'!$D$22:$AH$22) -> 31 | Q22: =COUNTIF('1. Datos brutos'!$D$22:$AH$22,">30") -> 0 | R22: =COUNTIF('1. Datos brutos'!$D$22:$AH$22,"<0") -> 0
A23: NLD | B23: P. Bajos | C23: Eurozona core | D23: =AVERAGE('1. Datos brutos'!$D$23:$AH$23) -> 2.286129 | E23: =STDEV('1. Datos brutos'!$D$23:$AH$23) -> 1.6697938 | F23: =MIN('1. Datos brutos'!$D$23:$AH$23) -> 0.32 | G23: =INDEX('1. Datos brutos'!$D$4:$AH$4,MATCH(MIN('1. Datos brutos'!$D$23:$AH$23),'1. Datos brutos'!$D$23:$AH$23,0)) -> 2016 | H23: =MAX('1. Datos brutos'!$D$23:$AH$23) -> 10 | I23: =AVERAGEIF('1. Datos brutos'!$D$23:$AH$23,"<=30") -> 2.286129 | J23: =STDEV(IF('1. Datos brutos'!$D$23:$AH$23<=30,'1. Datos brutos'!$D$23:$AH$23)) -> 1.6697938 | K23: =MEDIAN(IF('1. Datos brutos'!$D$23:$AH$23<=30,'1. Datos brutos'!$D$23:$AH$23)) -> 2.11 | L23: =IF(I23<>0,(J23/I23)*100,"") -> 73.040223 | M23: =PERCENTILE(IF('1. Datos brutos'!$D$23:$AH$23<=30,'1. Datos brutos'!$D$23:$AH$23),0.75)-PERCENTILE(IF('1. Datos brutos'!$D$23:$AH$23<=30,'1. Datos brutos'!$D$23:$AH$23),0.25) -> 1.215 | N23: =PERCENTILE(IF('1. Datos brutos'!$D$23:$AH$23<=30,'1. Datos brutos'!$D$23:$AH$23),0.25) -> 1.33 | O23: =PERCENTILE(IF('1. Datos brutos'!$D$23:$AH$23<=30,'1. Datos brutos'!$D$23:$AH$23),0.75) -> 2.545 | P23: =COUNT('1. Datos brutos'!$D$23:$AH$23) -> 31 | Q23: =COUNTIF('1. Datos brutos'!$D$23:$AH$23,">30") -> 0 | R23: =COUNTIF('1. Datos brutos'!$D$23:$AH$23,"<0") -> 0
A24: PRT | B24: Portugal | C24: Eurozona core | D24: =AVERAGE('1. Datos brutos'!$D$24:$AH$24) -> 2.5080645 | E24: =STDEV('1. Datos brutos'!$D$24:$AH$24) -> 1.9813555 | F24: =MIN('1. Datos brutos'!$D$24:$AH$24) -> -0.84 | G24: =INDEX('1. Datos brutos'!$D$4:$AH$4,MATCH(MIN('1. Datos brutos'!$D$24:$AH$24),'1. Datos brutos'!$D$24:$AH$24,0)) -> 2009 | H24: =MAX('1. Datos brutos'!$D$24:$AH$24) -> 7.83 | I24: =AVERAGEIF('1. Datos brutos'!$D$24:$AH$24,"<=30") -> 2.5080645 | J24: =STDEV(IF('1. Datos brutos'!$D$24:$AH$24<=30,'1. Datos brutos'!$D$24:$AH$24)) -> 1.9813555 | K24: =MEDIAN(IF('1. Datos brutos'!$D$24:$AH$24<=30,'1. Datos brutos'!$D$24:$AH$24)) -> 2.45 | L24: =IF(I24<>0,(J24/I24)*100,"") -> 78.999382 | M24: =PERCENTILE(IF('1. Datos brutos'!$D$24:$AH$24<=30,'1. Datos brutos'!$D$24:$AH$24),0.75)-PERCENTILE(IF('1. Datos brutos'!$D$24:$AH$24<=30,'1. Datos brutos'!$D$24:$AH$24),0.25) -> 2.28 | N24: =PERCENTILE(IF('1. Datos brutos'!$D$24:$AH$24<=30,'1. Datos brutos'!$D$24:$AH$24),0.25) -> 1.13 | O24: =PERCENTILE(IF('1. Datos brutos'!$D$24:$AH$24<=30,'1. Datos brutos'!$D$24:$AH$24),0.75) -> 3.41 | P24: =COUNT('1. Datos brutos'!$D$24:$AH$24) -> 31 | Q24: =COUNTIF('1. Datos brutos'!$D$24:$AH$24,">30") -> 0 | R24: =COUNTIF('1. Datos brutos'!$D$24:$AH$24,"<0") -> 3
A25: USA | B25: EE.UU. | C25: EE.UU. | D25: =AVERAGE('1. Datos brutos'!$D$25:$AH$25) -> 2.5432258 | E25: =STDEV('1. Datos brutos'!$D$25:$AH$25) -> 1.4724501 | F25: =MIN('1. Datos brutos'!$D$25:$AH$25) -> -0.36 | G25: =INDEX('1. Datos brutos'!$D$4:$AH$4,MATCH(MIN('1. Datos brutos'!$D$25:$AH$25),'1. Datos brutos'!$D$25:$AH$25,0)) -> 2009 | H25: =MAX('1. Datos brutos'!$D$25:$AH$25) -> 8 | I25: =AVERAGEIF('1. Datos brutos'!$D$25:$AH$25,"<=30") -> 2.5432258 | J25: =STDEV(IF('1. Datos brutos'!$D$25:$AH$25<=30,'1. Datos brutos'!$D$25:$AH$25)) -> 1.4724501 | K25: =MEDIAN(IF('1. Datos brutos'!$D$25:$AH$25<=30,'1. Datos brutos'!$D$25:$AH$25)) -> 2.44 | L25: =IF(I25<>0,(J25/I25)*100,"") -> 57.896946 | M25: =PERCENTILE(IF('1. Datos brutos'!$D$25:$AH$25<=30,'1. Datos brutos'!$D$25:$AH$25),0.75)-PERCENTILE(IF('1. Datos brutos'!$D$25:$AH$25<=30,'1. Datos brutos'!$D$25:$AH$25),0.25) -> 1.425 | N25: =PERCENTILE(IF('1. Datos brutos'!$D$25:$AH$25<=30,'1. Datos brutos'!$D$25:$AH$25),0.25) -> 1.63 | O25: =PERCENTILE(IF('1. Datos brutos'!$D$25:$AH$25<=30,'1. Datos brutos'!$D$25:$AH$25),0.75) -> 3.055 | P25: =COUNT('1. Datos brutos'!$D$25:$AH$25) -> 31 | Q25: =COUNTIF('1. Datos brutos'!$D$25:$AH$25,">30") -> 0 | R25: =COUNTIF('1. Datos brutos'!$D$25:$AH$25,"<0") -> 1
A26: GBR | B26: Reino Unido | C26: Reino Unido | D26: =AVERAGE('1. Datos brutos'!$D$26:$AH$26) -> 2.3990323 | E26: =STDEV('1. Datos brutos'!$D$26:$AH$26) -> 1.5180236 | F26: =MIN('1. Datos brutos'!$D$26:$AH$26) -> 0.37 | G26: =INDEX('1. Datos brutos'!$D$4:$AH$4,MATCH(MIN('1. Datos brutos'!$D$26:$AH$26),'1. Datos brutos'!$D$26:$AH$26,0)) -> 2015 | H26: =MAX('1. Datos brutos'!$D$26:$AH$26) -> 7.92 | I26: =AVERAGEIF('1. Datos brutos'!$D$26:$AH$26,"<=30") -> 2.3990323 | J26: =STDEV(IF('1. Datos brutos'!$D$26:$AH$26<=30,'1. Datos brutos'!$D$26:$AH$26)) -> 1.5180236 | K26: =MEDIAN(IF('1. Datos brutos'!$D$26:$AH$26<=30,'1. Datos brutos'!$D$26:$AH$26)) -> 2.22 | L26: =IF(I26<>0,(J26/I26)*100,"") -> 63.276499 | M26: =PERCENTILE(IF('1. Datos brutos'!$D$26:$AH$26<=30,'1. Datos brutos'!$D$26:$AH$26),0.75)-PERCENTILE(IF('1. Datos brutos'!$D$26:$AH$26<=30,'1. Datos brutos'!$D$26:$AH$26),0.25) -> 1.035 | N26: =PERCENTILE(IF('1. Datos brutos'!$D$26:$AH$26<=30,'1. Datos brutos'!$D$26:$AH$26),0.25) -> 1.525 | O26: =PERCENTILE(IF('1. Datos brutos'!$D$26:$AH$26<=30,'1. Datos brutos'!$D$26:$AH$26),0.75) -> 2.56 | P26: =COUNT('1. Datos brutos'!$D$26:$AH$26) -> 31 | Q26: =COUNTIF('1. Datos brutos'!$D$26:$AH$26,">30") -> 0 | R26: =COUNTIF('1. Datos brutos'!$D$26:$AH$26,"<0") -> 0

Sheet 3. Mapa de calor
A1: MAPA DE CALOR — Fórmula: =SI(ESNUMERO(ref),SI(ref>30,"Hiper.",ref),"") · Colores aplicados por rangos
A2: Cada celda referencia directamente '1. Datos brutos'. Los colores son fijos (no fórmula) para ser compatibles con Word.
A3: Leyenda: | C3: Deflación (<0%) | D3: 0–2% | E3: 2–5% | F3: 5–10% | G3: >10% | H3: Hiper. (>30%)
A5: País | B5: Grupo | C5: 1993 | D5: 1994 | E5: 1995 | F5: 1996 | G5: 1997 | H5: 1998 | I5: 1999 | J5: 2000 | K5: 2001 | L5: 2002 | M5: 2003 | N5: 2004 | O5: 2005 | P5: 2006 | Q5: 2007 | R5: 2008 | S5: 2009 | T5: 2010 | U5: 2011 | V5: 2012 | W5: 2013 | X5: 2014 | Y5: 2015 | Z5: 2016 | AA5: 2017 | AB5: 2018 | AC5: 2019 | AD5: 2020 | AE5: 2021 | AF5: 2022 | AG5: 2023 | AH5: 2024 | AI5: 2025
A6: ='1. Datos brutos'!B5 -> Alemania | B6: ='1. Datos brutos'!C5 -> Eurozona core | C6: =IF(ISNUMBER('1. Datos brutos'!D5),IF('1. Datos brutos'!D5>30,"Hiper.",'1. Datos brutos'!D5),"") -> 4.47 | D6: =IF(ISNUMBER('1. Datos brutos'!E5),IF('1. Datos brutos'!E5>30,"Hiper.",'1. Datos brutos'!E5),"") -> 2.69 | E6: =IF(ISNUMBER('1. Datos brutos'!F5),IF('1. Datos brutos'!F5>30,"Hiper.",'1. Datos brutos'!F5),"") -> 1.71 | F6: =IF(ISNUMBER('1. Datos brutos'!G5),IF('1. Datos brutos'!G5>30,"Hiper.",'1. Datos brutos'!G5),"") -> 1.45 | G6: =IF(ISNUMBER('1. Datos brutos'!H5),IF('1. Datos brutos'!H5>30,"Hiper.",'1. Datos brutos'!H5),"") -> 1.94 | H6: =IF(ISNUMBER('1. Datos brutos'!I5),IF('1. Datos brutos'!I5>30,"Hiper.",'1. Datos brutos'!I5),"") -> 0.91 | I6: =IF(ISNUMBER('1. Datos brutos'!J5),IF('1. Datos brutos'!J5>30,"Hiper.",'1. Datos brutos'!J5),"") -> 0.59 | J6: =IF(ISNUMBER('1. Datos brutos'!K5),IF('1. Datos brutos'!K5>30,"Hiper.",'1. Datos brutos'!K5),"") -> 1.44 | ... AI6: =IF(ISNUMBER('1. Datos brutos'!AJ5),IF('1. Datos brutos'!AJ5>30,"Hiper.",'1. Datos brutos'!AJ5),"") -> 0
A7: ='1. Datos brutos'!B6 -> Austria | B7: ='1. Datos brutos'!C6 -> Eurozona core | C7: =IF(ISNUMBER('1. Datos brutos'!D6),IF('1. Datos brutos'!D6>30,"Hiper.",'1. Datos brutos'!D6),"") -> 3.63 | D7: =IF(ISNUMBER('1. Datos brutos'!E6),IF('1. Datos brutos'!E6>30,"Hiper.",'1. Datos brutos'!E6),"") -> 2.95 | E7: =IF(ISNUMBER('1. Datos brutos'!F6),IF('1. Datos brutos'!F6>30,"Hiper.",'1. Datos brutos'!F6),"") -> 2.24 | F7: =IF(ISNUMBER('1. Datos brutos'!G6),IF('1. Datos brutos'!G6>30,"Hiper.",'1. Datos brutos'!G6),"") -> 1.86 | G7: =IF(ISNUMBER('1. Datos brutos'!H6),IF('1. Datos brutos'!H6>30,"Hiper.",'1. Datos brutos'!H6),"") -> 1.31 | H7: =IF(ISNUMBER('1. Datos brutos'!I6),IF('1. Datos brutos'!I6>30,"Hiper.",'1. Datos brutos'!I6),"") -> 0.92 | I7: =IF(ISNUMBER('1. Datos brutos'!J6),IF('1. Datos brutos'!J6>30,"Hiper.",'1. Datos brutos'!J6),"") -> 0.57 | J7: =IF(ISNUMBER('1. Datos brutos'!K6),IF('1. Datos brutos'!K6>30,"Hiper.",'1. Datos brutos'!K6),"") -> 2.34 | ... AI7: =IF(ISNUMBER('1. Datos brutos'!AJ6),IF('1. Datos brutos'!AJ6>30,"Hiper.",'1. Datos brutos'!AJ6),"") -> 0
A8: ='1. Datos brutos'!B7 -> Bélgica | B8: ='1. Datos brutos'!C7 -> Eurozona core | C8: =IF(ISNUMBER('1. Datos brutos'!D7),IF('1. Datos brutos'!D7>30,"Hiper.",'1. Datos brutos'!D7),"") -> 2.75 | D8: =IF(ISNUMBER('1. Datos brutos'!E7),IF('1. Datos brutos'!E7>30,"Hiper.",'1. Datos brutos'!E7),"") -> 2.38 | E8: =IF(ISNUMBER('1. Datos brutos'!F7),IF('1. Datos brutos'!F7>30,"Hiper.",'1. Datos brutos'!F7),"") -> 1.47 | F8: =IF(ISNUMBER('1. Datos brutos'!G7),IF('1. Datos brutos'!G7>30,"Hiper.",'1. Datos brutos'!G7),"") -> 2.08 | G8: =IF(ISNUMBER('1. Datos brutos'!H7),IF('1. Datos brutos'!H7>30,"Hiper.",'1. Datos brutos'!H7),"") -> 1.63 | H8: =IF(ISNUMBER('1. Datos brutos'!I7),IF('1. Datos brutos'!I7>30,"Hiper.",'1. Datos brutos'!I7),"") -> 0.95 | I8: =IF(ISNUMBER('1. Datos brutos'!J7),IF('1. Datos brutos'!J7>30,"Hiper.",'1. Datos brutos'!J7),"") -> 1.12 | J8: =IF(ISNUMBER('1. Datos brutos'!K7),IF('1. Datos brutos'!K7>30,"Hiper.",'1. Datos brutos'!K7),"") -> 2.54 | ... AI8: =IF(ISNUMBER('1. Datos brutos'!AJ7),IF('1. Datos brutos'!AJ7>30,"Hiper.",'1. Datos brutos'!AJ7),"") -> 0
A9: ='1. Datos brutos'!B8 -> Chipre | B9: ='1. Datos brutos'!C8 -> Eurozona core | C9: =IF(ISNUMBER('1. Datos brutos'!D8),IF('1. Datos brutos'!D8>30,"Hiper.",'1. Datos brutos'!D8),"") -> 4.85 | D9: =IF(ISNUMBER('1. Datos brutos'!E8),IF('1. Datos brutos'!E8>30,"Hiper.",'1. Datos brutos'!E8),"") -> 4.7 | E9: =IF(ISNUMBER('1. Datos brutos'!F8),IF('1. Datos brutos'!F8>30,"Hiper.",'1. Datos brutos'!F8),"") -> 2.62 | F9: =IF(ISNUMBER('1. Datos brutos'!G8),IF('1. Datos brutos'!G8>30,"Hiper.",'1. Datos brutos'!G8),"") -> 2.98 | G9: =IF(ISNUMBER('1. Datos brutos'!H8),IF('1. Datos brutos'!H8>30,"Hiper.",'1. Datos brutos'!H8),"") -> 3.61 | H9: =IF(ISNUMBER('1. Datos brutos'!I8),IF('1. Datos brutos'!I8>30,"Hiper.",'1. Datos brutos'!I8),"") -> 2.23 | I9: =IF(ISNUMBER('1. Datos brutos'!J8),IF('1. Datos brutos'!J8>30,"Hiper.",'1. Datos brutos'!J8),"") -> 1.63 | J9: =IF(ISNUMBER('1. Datos brutos'!K8),IF('1. Datos brutos'!K8>30,"Hiper.",'1. Datos brutos'!K8),"") -> 4.14 | ... AI9: =IF(ISNUMBER('1. Datos brutos'!AJ8),IF('1. Datos brutos'!AJ8>30,"Hiper.",'1. Datos brutos'!AJ8),"") -> 0
A10: ='1. Datos brutos'!B9 -> Croacia | B10: ='1. Datos brutos'!C9 -> Eurozona core | C10: =IF(ISNUMBER('1. Datos brutos'!D9),IF('1. Datos brutos'!D9>30,"Hiper.",'1. Datos brutos'!D9),"") -> Hiper. | D10: =IF(ISNUMBER('1. Datos brutos'!E9),IF('1. Datos brutos'!E9>30,"Hiper.",'1. Datos brutos'!E9),"") -> Hiper. | E10: =IF(ISNUMBER('1. Datos brutos'!F9),IF('1. Datos brutos'!F9>30,"Hiper.",'1. Datos brutos'!F9),"") -> 3.95 | F10: =IF(ISNUMBER('1. Datos brutos'!G9),IF('1. Datos brutos'!G9>30,"Hiper.",'1. Datos brutos'!G9),"") -> 4.3 | G10: =IF(ISNUMBER('1. Datos brutos'!H9),IF('1. Datos brutos'!H9>30,"Hiper.",'1. Datos brutos'!H9),"") -> 4.17 | H10: =IF(ISNUMBER('1. Datos brutos'!I9),IF('1. Datos brutos'!I9>30,"Hiper.",'1. Datos brutos'!I9),"") -> 6.4 | I10: =IF(ISNUMBER('1. Datos brutos'!J9),IF('1. Datos brutos'!J9>30,"Hiper.",'1. Datos brutos'!J9),"") -> 4.02 | J10: =IF(ISNUMBER('1. Datos brutos'!K9),IF('1. Datos brutos'!K9>30,"Hiper.",'1. Datos brutos'!K9),"") -> 4.61 | ... AI10: =IF(ISNUMBER('1. Datos brutos'!AJ9),IF('1. Datos brutos'!AJ9>30,"Hiper.",'1. Datos brutos'!AJ9),"") -> 0
A11: ='1. Datos brutos'!B10 -> Eslovaquia | B11: ='1. Datos brutos'!C10 -> Eurozona core | C11: =IF(ISNUMBER('1. Datos brutos'!D10),IF('1. Datos brutos'!D10>30,"Hiper.",'1. Datos brutos'!D10),"") -> 23.29 | D11: =IF(ISNUMBER('1. Datos brutos'!E10),IF('1. Datos brutos'!E10>30,"Hiper.",'1. Datos brutos'!E10),"") -> 13.42 | E11: =IF(ISNUMBER('1. Datos brutos'!F10),IF('1. Datos brutos'!F10>30,"Hiper.",'1. Datos brutos'!F10),"") -> 9.84 | F11: =IF(ISNUMBER('1. Datos brutos'!G10),IF('1. Datos brutos'!G10>30,"Hiper.",'1. Datos brutos'!G10),"") -> 5.78 | G11: =IF(ISNUMBER('1. Datos brutos'!H10),IF('1. Datos brutos'!H10>30,"Hiper.",'1. Datos brutos'!H10),"") -> 6.14 | H11: =IF(ISNUMBER('1. Datos brutos'!I10),IF('1. Datos brutos'!I10>30,"Hiper.",'1. Datos brutos'!I10),"") -> 6.67 | I11: =IF(ISNUMBER('1. Datos brutos'!J10),IF('1. Datos brutos'!J10>30,"Hiper.",'1. Datos brutos'!J10),"") -> 10.57 | J11: =IF(ISNUMBER('1. Datos brutos'!K10),IF('1. Datos brutos'!K10>30,"Hiper.",'1. Datos brutos'!K10),"") -> 12.04 | ... AI11: =IF(ISNUMBER('1. Datos brutos'!AJ10),IF('1. Datos brutos'!AJ10>30,"Hiper.",'1. Datos brutos'!AJ10),"") -> 0
A12: ='1. Datos brutos'!B11 -> Eslovenia | B12: ='1. Datos brutos'!C11 -> Eurozona core | C12: =IF(ISNUMBER('1. Datos brutos'!D11),IF('1. Datos brutos'!D11>30,"Hiper.",'1. Datos brutos'!D11),"") -> Hiper. | D12: =IF(ISNUMBER('1. Datos brutos'!E11),IF('1. Datos brutos'!E11>30,"Hiper.",'1. Datos brutos'!E11),"") -> 20.99 | E12: =IF(ISNUMBER('1. Datos brutos'!F11),IF('1. Datos brutos'!F11>30,"Hiper.",'1. Datos brutos'!F11),"") -> 13.46 | F12: =IF(ISNUMBER('1. Datos brutos'!G11),IF('1. Datos brutos'!G11>30,"Hiper.",'1. Datos brutos'!G11),"") -> 9.86 | G12: =IF(ISNUMBER('1. Datos brutos'!H11),IF('1. Datos brutos'!H11>30,"Hiper.",'1. Datos brutos'!H11),"") -> 8.36 | H12: =IF(ISNUMBER('1. Datos brutos'!I11),IF('1. Datos brutos'!I11>30,"Hiper.",'1. Datos brutos'!I11),"") -> 7.89 | I12: =IF(ISNUMBER('1. Datos brutos'!J11),IF('1. Datos brutos'!J11>30,"Hiper.",'1. Datos brutos'!J11),"") -> 6.16 | J12: =IF(ISNUMBER('1. Datos brutos'!K11),IF('1. Datos brutos'!K11>30,"Hiper.",'1. Datos brutos'!K11),"") -> 8.91 | ... AI12: =IF(ISNUMBER('1. Datos brutos'!AJ11),IF('1. Datos brutos'!AJ11>30,"Hiper.",'1. Datos brutos'!AJ11),"") -> 0
A13: ='1. Datos brutos'!B12 -> España | B13: ='1. Datos brutos'!C12 -> Eurozona core | C13: =IF(ISNUMBER('1. Datos brutos'!D12),IF('1. Datos brutos'!D12>30,"Hiper.",'1. Datos brutos'!D12),"") -> 4.57 | D13: =IF(ISNUMBER('1. Datos brutos'!E12),IF('1. Datos brutos'!E12>30,"Hiper.",'1. Datos brutos'!E12),"") -> 4.72 | E13: =IF(ISNUMBER('1. Datos brutos'!F12),IF('1. Datos brutos'!F12>30,"Hiper.",'1. Datos brutos'!F12),"") -> 4.67 | F13: =IF(ISNUMBER('1. Datos brutos'!G12),IF('1. Datos brutos'!G12>30,"Hiper.",'1. Datos brutos'!G12),"") -> 3.56 | G13: =IF(ISNUMBER('1. Datos brutos'!H12),IF('1. Datos brutos'!H12>30,"Hiper.",'1. Datos brutos'!H12),"") -> 1.97 | H13: =IF(ISNUMBER('1. Datos brutos'!I12),IF('1. Datos brutos'!I12>30,"Hiper.",'1. Datos brutos'!I12),"") -> 1.83 | I13: =IF(ISNUMBER('1. Datos brutos'!J12),IF('1. Datos brutos'!J12>30,"Hiper.",'1. Datos brutos'!J12),"") -> 2.31 | J13: =IF(ISNUMBER('1. Datos brutos'!K12),IF('1. Datos brutos'!K12>30,"Hiper.",'1. Datos brutos'!K12),"") -> 3.43 | ... AI13: =IF(ISNUMBER('1. Datos brutos'!AJ12),IF('1. Datos brutos'!AJ12>30,"Hiper.",'1. Datos brutos'!AJ12),"") -> 0
A14: ='1. Datos brutos'!B13 -> Estonia | B14: ='1. Datos brutos'!C13 -> Bálticos | C14: =IF(ISNUMBER('1. Datos brutos'!D13),IF('1. Datos brutos'!D13>30,"Hiper.",'1. Datos brutos'!D13),"") -> Hiper. | D14: =IF(ISNUMBER('1. Datos brutos'!E13),IF('1. Datos brutos'!E13>30,"Hiper.",'1. Datos brutos'!E13),"") -> Hiper. | E14: =IF(ISNUMBER('1. Datos brutos'!F13),IF('1. Datos brutos'!F13>30,"Hiper.",'1. Datos brutos'!F13),"") -> 28.78 | F14: =IF(ISNUMBER('1. Datos brutos'!G13),IF('1. Datos brutos'!G13>30,"Hiper.",'1. Datos brutos'!G13),"") -> 23.05 | G14: =IF(ISNUMBER('1. Datos brutos'!H13),IF('1. Datos brutos'!H13>30,"Hiper.",'1. Datos brutos'!H13),"") -> 10.58 | H14: =IF(ISNUMBER('1. Datos brutos'!I13),IF('1. Datos brutos'!I13>30,"Hiper.",'1. Datos brutos'!I13),"") -> 8.21 | I14: =IF(ISNUMBER('1. Datos brutos'!J13),IF('1. Datos brutos'!J13>30,"Hiper.",'1. Datos brutos'!J13),"") -> 3.3 | J14: =IF(ISNUMBER('1. Datos brutos'!K13),IF('1. Datos brutos'!K13>30,"Hiper.",'1. Datos brutos'!K13),"") -> 4.02 | ... AI14: =IF(ISNUMBER('1. Datos brutos'!AJ13),IF('1. Datos brutos'!AJ13>30,"Hiper.",'1. Datos brutos'!AJ13),"") -> 0
A15: ='1. Datos brutos'!B14 -> Finlandia | B15: ='1. Datos brutos'!C14 -> Eurozona core | C15: =IF(ISNUMBER('1. Datos brutos'!D14),IF('1. Datos brutos'!D14>30,"Hiper.",'1. Datos brutos'!D14),"") -> 2.19 | D15: =IF(ISNUMBER('1. Datos brutos'!E14),IF('1. Datos brutos'!E14>30,"Hiper.",'1. Datos brutos'!E14),"") -> 1.09 | E15: =IF(ISNUMBER('1. Datos brutos'!F14),IF('1. Datos brutos'!F14>30,"Hiper.",'1. Datos brutos'!F14),"") -> 0.79 | F15: =IF(ISNUMBER('1. Datos brutos'!G14),IF('1. Datos brutos'!G14>30,"Hiper.",'1. Datos brutos'!G14),"") -> 0.63 | G15: =IF(ISNUMBER('1. Datos brutos'!H14),IF('1. Datos brutos'!H14>30,"Hiper.",'1. Datos brutos'!H14),"") -> 1.19 | H15: =IF(ISNUMBER('1. Datos brutos'!I14),IF('1. Datos brutos'!I14>30,"Hiper.",'1. Datos brutos'!I14),"") -> 1.4 | I15: =IF(ISNUMBER('1. Datos brutos'!J14),IF('1. Datos brutos'!J14>30,"Hiper.",'1. Datos brutos'!J14),"") -> 1.16 | J15: =IF(ISNUMBER('1. Datos brutos'!K14),IF('1. Datos brutos'!K14>30,"Hiper.",'1. Datos brutos'!K14),"") -> 3.04 | ... AI15: =IF(ISNUMBER('1. Datos brutos'!AJ14),IF('1. Datos brutos'!AJ14>30,"Hiper.",'1. Datos brutos'!AJ14),"") -> 0
A16: ='1. Datos brutos'!B15 -> Francia | B16: ='1. Datos brutos'!C15 -> Eurozona core | C16: =IF(ISNUMBER('1. Datos brutos'!D15),IF('1. Datos brutos'!D15>30,"Hiper.",'1. Datos brutos'!D15),"") -> 2.1 | D16: =IF(ISNUMBER('1. Datos brutos'!E15),IF('1. Datos brutos'!E15>30,"Hiper.",'1. Datos brutos'!E15),"") -> 1.66 | E16: =IF(ISNUMBER('1. Datos brutos'!F15),IF('1. Datos brutos'!F15>30,"Hiper.",'1. Datos brutos'!F15),"") -> 1.8 | F16: =IF(ISNUMBER('1. Datos brutos'!G15),IF('1. Datos brutos'!G15>30,"Hiper.",'1. Datos brutos'!G15),"") -> 1.98 | G16: =IF(ISNUMBER('1. Datos brutos'!H15),IF('1. Datos brutos'!H15>30,"Hiper.",'1. Datos brutos'!H15),"") -> 1.2 | H16: =IF(ISNUMBER('1. Datos brutos'!I15),IF('1. Datos brutos'!I15>30,"Hiper.",'1. Datos brutos'!I15),"") -> 0.65 | I16: =IF(ISNUMBER('1. Datos brutos'!J15),IF('1. Datos brutos'!J15>30,"Hiper.",'1. Datos brutos'!J15),"") -> 0.54 | J16: =IF(ISNUMBER('1. Datos brutos'!K15),IF('1. Datos brutos'!K15>30,"Hiper.",'1. Datos brutos'!K15),"") -> 1.68 | ... AI16: =IF(ISNUMBER('1. Datos brutos'!AJ15),IF('1. Datos brutos'!AJ15>30,"Hiper.",'1. Datos brutos'!AJ15),"") -> 0
A17: ='1. Datos brutos'!B16 -> Grecia | B17: ='1. Datos brutos'!C16 -> Eurozona core | C17: =IF(ISNUMBER('1. Datos brutos'!D16),IF('1. Datos brutos'!D16>30,"Hiper.",'1. Datos brutos'!D16),"") -> 14.41 | D17: =IF(ISNUMBER('1. Datos brutos'!E16),IF('1. Datos brutos'!E16>30,"Hiper.",'1. Datos brutos'!E16),"") -> 10.87 | E17: =IF(ISNUMBER('1. Datos brutos'!F16),IF('1. Datos brutos'!F16>30,"Hiper.",'1. Datos brutos'!F16),"") -> 8.93 | F17: =IF(ISNUMBER('1. Datos brutos'!G16),IF('1. Datos brutos'!G16>30,"Hiper.",'1. Datos brutos'!G16),"") -> 8.19 | G17: =IF(ISNUMBER('1. Datos brutos'!H16),IF('1. Datos brutos'!H16>30,"Hiper.",'1. Datos brutos'!H16),"") -> 5.54 | H17: =IF(ISNUMBER('1. Datos brutos'!I16),IF('1. Datos brutos'!I16>30,"Hiper.",'1. Datos brutos'!I16),"") -> 4.77 | I17: =IF(ISNUMBER('1. Datos brutos'!J16),IF('1. Datos brutos'!J16>30,"Hiper.",'1. Datos brutos'!J16),"") -> 2.64 | J17: =IF(ISNUMBER('1. Datos brutos'!K16),IF('1. Datos brutos'!K16>30,"Hiper.",'1. Datos brutos'!K16),"") -> 3.15 | ... AI17: =IF(ISNUMBER('1. Datos brutos'!AJ16),IF('1. Datos brutos'!AJ16>30,"Hiper.",'1. Datos brutos'!AJ16),"") -> 0
... A27: ='1. Datos brutos'!B26 -> Reino Unido | B27: ='1. Datos brutos'!C26 -> Reino Unido | C27: =IF(ISNUMBER('1. Datos brutos'!D26),IF('1. Datos brutos'!D26>30,"Hiper.",'1. Datos brutos'!D26),"") -> 2.56 | D27: =IF(ISNUMBER('1. Datos brutos'!E26),IF('1. Datos brutos'!E26>30,"Hiper.",'1. Datos brutos'!E26),"") -> 2.22 | E27: =IF(ISNUMBER('1. Datos brutos'!F26),IF('1. Datos brutos'!F26>30,"Hiper.",'1. Datos brutos'!F26),"") -> 2.7 | F27: =IF(ISNUMBER('1. Datos brutos'!G26),IF('1. Datos brutos'!G26>30,"Hiper.",'1. Datos brutos'!G26),"") -> 2.85 | G27: =IF(ISNUMBER('1. Datos brutos'!H26),IF('1. Datos brutos'!H26>30,"Hiper.",'1. Datos brutos'!H26),"") -> 2.2 | H27: =IF(ISNUMBER('1. Datos brutos'!I26),IF('1. Datos brutos'!I26>30,"Hiper.",'1. Datos brutos'!I26),"") -> 1.82 | I27: =IF(ISNUMBER('1. Datos brutos'!J26),IF('1. Datos brutos'!J26>30,"Hiper.",'1. Datos brutos'!J26),"") -> 1.75 | J27: =IF(ISNUMBER('1. Datos brutos'!K26),IF('1. Datos brutos'!K26>30,"Hiper.",'1. Datos brutos'!K26),"") -> 1.18 | ... AI27: =IF(ISNUMBER('1. Datos brutos'!AJ26),IF('1. Datos brutos'!AJ26>30,"Hiper.",'1. Datos brutos'!AJ26),"") -> 0

Sheet 4. Evolución agrupada
A1: EVOLUCIÓN AGRUPADA — Fórmulas AVERAGEIF / AVERAGEIFS sobre '1. Datos brutos' · Col C = grupo
A2: Grupos: Eurozona core (17 países) · Bálticos: EST,LVA,LTU · Reino Unido: GBR · EE.UU.: USA
A5: Año | B5: Eurozona core =AVERAGEIF(grupo,"Eurozona core",año) | C5: Bálticos (con hiper.) =AVERAGEIF(grupo,"Bálticos",año) | D5: Bálticos limpio =AVERAGEIFS(año,grupo,"Bálticos",año,"<=30") | E5: Reino Unido =AVERAGEIF(grupo,"Reino Unido",año) | F5: EE.UU. =AVERAGEIF(grupo,"EE.UU.",año) | G5: Media global =AVERAGE(año) | H5: Desv.típ. global =STDEV(año)
A6: 1993 | B6: =AVERAGEIF('1. Datos brutos'!$C$5:$C$26,"Eurozona core",'1. Datos brutos'!$D$5:$D$26) -> 95.13 | C6: =AVERAGEIF('1. Datos brutos'!$C$5:$C$26,"Bálticos",'1. Datos brutos'!$D$5:$D$26) -> 203.08333 | D6: =AVERAGEIFS('1. Datos brutos'!$D$5:$D$26,'1. Datos brutos'!$C$5:$C$26,"Bálticos",'1. Datos brutos'!$D$5:$D$26,"<=30") -> #DIV/0! | E6: =AVERAGEIF('1. Datos brutos'!$C$5:$C$26,"Reino Unido",'1. Datos brutos'!$D$5:$D$26) -> 2.56 | F6: =AVERAGEIF('1. Datos brutos'!$C$5:$C$26,"EE.UU.",'1. Datos brutos'!$D$5:$D$26) -> 2.95 | G6: =AVERAGE('1. Datos brutos'!$D$5:$D$26) -> 101.45318 | H6: =STDEV('1. Datos brutos'!$D$5:$D$26) -> 324.69385
A7: 1994 | B7: =AVERAGEIF('1. Datos brutos'!$C$5:$C$26,"Eurozona core",'1. Datos brutos'!$E$5:$E$26) -> 11.394118 | C7: =AVERAGEIF('1. Datos brutos'!$C$5:$C$26,"Bálticos",'1. Datos brutos'!$E$5:$E$26) -> 51.94 | D7: =AVERAGEIFS('1. Datos brutos'!$E$5:$E$26,'1. Datos brutos'!$C$5:$C$26,"Bálticos",'1. Datos brutos'!$E$5:$E$26,"<=30") -> #DIV/0! | E7: =AVERAGEIF('1. Datos brutos'!$C$5:$C$26,"Reino Unido",'1. Datos brutos'!$E$5:$E$26) -> 2.22 | F7: =AVERAGEIF('1. Datos brutos'!$C$5:$C$26,"EE.UU.",'1. Datos brutos'!$E$5:$E$26) -> 2.61 | G7: =AVERAGE('1. Datos brutos'!$E$5:$E$26) -> 16.106818 | H7: =STDEV('1. Datos brutos'!$E$5:$E$26) -> 27.163006
A8: 1995 | B8: =AVERAGEIF('1. Datos brutos'!$C$5:$C$26,"Eurozona core",'1. Datos brutos'!$F$5:$F$26) -> 4.2164706 | C8: =AVERAGEIF('1. Datos brutos'!$C$5:$C$26,"Bálticos",'1. Datos brutos'!$F$5:$F$26) -> 31.136667 | D8: =AVERAGEIFS('1. Datos brutos'!$F$5:$F$26,'1. Datos brutos'!$C$5:$C$26,"Bálticos",'1. Datos brutos'!$F$5:$F$26,"<=30") -> 26.88 | E8: =AVERAGEIF('1. Datos brutos'!$C$5:$C$26,"Reino Unido",'1. Datos brutos'!$F$5:$F$26) -> 2.7 | F8: =AVERAGEIF('1. Datos brutos'!$C$5:$C$26,"EE.UU.",'1. Datos brutos'!$F$5:$F$26) -> 2.81 | G8: =AVERAGE('1. Datos brutos'!$F$5:$F$26) -> 7.7545455 | H8: =STDEV('1. Datos brutos'!$F$5:$F$26) -> 10.261071
A9: 1996 | B9: =AVERAGEIF('1. Datos brutos'!$C$5:$C$26,"Eurozona core",'1. Datos brutos'!$G$5:$G$26) -> 3.3441176 | C9: =AVERAGEIF('1. Datos brutos'!$C$5:$C$26,"Bálticos",'1. Datos brutos'!$G$5:$G$26) -> 21.763333 | D9: =AVERAGEIFS('1. Datos brutos'!$G$5:$G$26,'1. Datos brutos'!$C$5:$C$26,"Bálticos",'1. Datos brutos'!$G$5:$G$26,"<=30") -> 21.763333 | E9: =AVERAGEIF('1. Datos brutos'!$C$5:$C$26,"Reino Unido",'1. Datos brutos'!$G$5:$G$26) -> 2.85 | F9: =AVERAGEIF('1. Datos brutos'!$C$5:$C$26,"EE.UU.",'1. Datos brutos'!$G$5:$G$26) -> 2.93 | G9: =AVERAGE('1. Datos brutos'!$G$5:$G$26) -> 5.8145455 | H9: =STDEV('1. Datos brutos'!$G$5:$G$26) -> 6.9404465
A10: 1997 | B10: =AVERAGEIF('1. Datos brutos'!$C$5:$C$26,"Eurozona core",'1. Datos brutos'!$H$5:$H$26) -> 2.9158824 | C10: =AVERAGEIF('1. Datos brutos'!$C$5:$C$26,"Bálticos",'1. Datos brutos'!$H$5:$H$26) -> 9.3033333 | D10: =AVERAGEIFS('1. Datos brutos'!$H$5:$H$26,'1. Datos brutos'!$C$5:$C$26,"Bálticos",'1. Datos brutos'!$H$5:$H$26,"<=30") -> 9.3033333 | E10: =AVERAGEIF('1. Datos brutos'!$C$5:$C$26,"Reino Unido",'1. Datos brutos'!$H$5:$H$26) -> 2.2 | F10: =AVERAGEIF('1. Datos brutos'!$C$5:$C$26,"EE.UU.",'1. Datos brutos'!$H$5:$H$26) -> 2.34 | G10: =AVERAGE('1. Datos brutos'!$H$5:$H$26) -> 3.7281818 | H10: =STDEV('1. Datos brutos'!$H$5:$H$26) -> 2.9139135
A11: 1998 | B11: =AVERAGEIF('1. Datos brutos'!$C$5:$C$26,"Eurozona core",'1. Datos brutos'!$I$5:$I$26) -> 2.7570588 | C11: =AVERAGEIF('1. Datos brutos'!$C$5:$C$26,"Bálticos",'1. Datos brutos'!$I$5:$I$26) -> 5.9733333 | D11: =AVERAGEIFS('1. Datos brutos'!$I$5:$I$26,'1. Datos brutos'!$C$5:$C$26,"Bálticos",'1. Datos brutos'!$I$5:$I$26,"<=30") -> 5.9733333 | E11: =AVERAGEIF('1. Datos brutos'!$C$5:$C$26,"Reino Unido",'1. Datos brutos'!$I$5:$I$26) -> 1.82 | F11: =AVERAGEIF('1. Datos brutos'!$C$5:$C$26,"EE.UU.",'1. Datos brutos'!$I$5:$I$26) -> 1.55 | G11: =AVERAGE('1. Datos brutos'!$I$5:$I$26) -> 3.0981818 | H11: =STDEV('1. Datos brutos'!$I$5:$I$26) -> 2.3869339
A12: 1999 | B12: =AVERAGEIF('1. Datos brutos'!$C$5:$C$26,"Eurozona core",'1. Datos brutos'!$J$5:$J$26) -> 2.4858824 | C12: =AVERAGEIF('1. Datos brutos'!$C$5:$C$26,"Bálticos",'1. Datos brutos'!$J$5:$J$26) -> 2.13 | D12: =AVERAGEIFS('1. Datos brutos'!$J$5:$J$26,'1. Datos brutos'!$C$5:$C$26,"Bálticos",'1. Datos brutos'!$J$5:$J$26,"<=30") -> 2.13 | E12: =AVERAGEIF('1. Datos brutos'!$C$5:$C$26,"Reino Unido",'1. Datos brutos'!$J$5:$J$26) -> 1.75 | F12: =AVERAGEIF('1. Datos brutos'!$C$5:$C$26,"EE.UU.",'1. Datos brutos'!$J$5:$J$26) -> 2.19 | G12: =AVERAGE('1. Datos brutos'!$J$5:$J$26) -> 2.3904545 | H12: =STDEV('1. Datos brutos'!$J$5:$J$26) -> 2.2323028
A13: 2000 | B13: =AVERAGEIF('1. Datos brutos'!$C$5:$C$26,"Eurozona core",'1. Datos brutos'!$K$5:$K$26) -> 3.8923529 | C13: =AVERAGEIF('1. Datos brutos'!$C$5:$C$26,"Bálticos",'1. Datos brutos'!$K$5:$K$26) -> 2.55 | D13: =AVERAGEIFS('1. Datos brutos'!$K$5:$K$26,'1. Datos brutos'!$C$5:$C$26,"Bálticos",'1. Datos brutos'!$K$5:$K$26,"<=30") -> 2.55 | E13: =AVERAGEIF('1. Datos brutos'!$C$5:$C$26,"Reino Unido",'1. Datos brutos'!$K$5:$K$26) -> 1.18 | F13: =AVERAGEIF('1. Datos brutos'!$C$5:$C$26,"EE.UU.",'1. Datos brutos'!$K$5:$K$26) -> 3.38 | G13: =AVERAGE('1. Datos brutos'!$K$5:$K$26) -> 3.5627273 | H13: =STDEV('1. Datos brutos'!$K$5:$K$26) -> 2.5357129
A14: 2001 | B14: =AVERAGEIF('1. Datos brutos'!$C$5:$C$26,"Eurozona core",'1. Datos brutos'!$L$5:$L$26) -> 3.6170588 | C14: =AVERAGEIF('1. Datos brutos'!$C$5:$C$26,"Bálticos",'1. Datos brutos'!$L$5:$L$26) -> 3.2033333 | D14: =AVERAGEIFS('1. Datos brutos'!$L$5:$L$26,'1. Datos brutos'!$C$5:$C$26,"Bálticos",'1. Datos brutos'!$L$5:$L$26,"<=30") -> 3.2033333 | E14: =AVERAGEIF('1. Datos brutos'!$C$5:$C$26,"Reino Unido",'1. Datos brutos'!$L$5:$L$26) -> 1.53 | F14: =AVERAGEIF('1. Datos brutos'!$C$5:$C$26,"EE.UU.",'1. Datos brutos'!$L$5:$L$26) -> 2.83 | G14: =AVERAGE('1. Datos brutos'!$L$5:$L$26) -> 3.43 | H14: =STDEV('1. Datos brutos'!$L$5:$L$26) -> 1.8094435
A15: 2002 | B15: =AVERAGEIF('1. Datos brutos'!$C$5:$C$26,"Eurozona core",'1. Datos brutos'!$M$5:$M$26) -> 2.8470588 | C15: =AVERAGEIF('1. Datos brutos'!$C$5:$C$26,"Bálticos",'1. Datos brutos'!$M$5:$M$26) -> 1.93 | D15: =AVERAGEIFS('1. Datos brutos'!$M$5:$M$26,'1. Datos brutos'!$C$5:$C$26,"Bálticos",'1. Datos brutos'!$M$5:$M$26,"<=30") -> 1.93 | E15: =AVERAGEIF('1. Datos brutos'!$C$5:$C$26,"Reino Unido",'1. Datos brutos'!$M$5:$M$26) -> 1.52 | F15: =AVERAGEIF('1. Datos brutos'!$C$5:$C$26,"EE.UU.",'1. Datos brutos'!$M$5:$M$26) -> 1.59 | G15: =AVERAGE('1. Datos brutos'!$M$5:$M$26) -> 2.6045455 | H15: =STDEV('1. Datos brutos'!$M$5:$M$26) -> 1.4757104
A16: 2003 | B16: =AVERAGEIF('1. Datos brutos'!$C$5:$C$26,"Eurozona core",'1. Datos brutos'!$N$5:$N$26) -> 2.8441176 | C16: =AVERAGEIF('1. Datos brutos'!$C$5:$C$26,"Bálticos",'1. Datos brutos'!$N$5:$N$26) -> 1.0466667 | D16: =AVERAGEIFS('1. Datos brutos'!$N$5:$N$26,'1. Datos brutos'!$C$5:$C$26,"Bálticos",'1. Datos brutos'!$N$5:$N$26,"<=30") -> 1.0466667 | E16: =AVERAGEIF('1. Datos brutos'!$C$5:$C$26,"Reino Unido",'1. Datos brutos'!$N$5:$N$26) -> 1.38 | F16: =AVERAGEIF('1. Datos brutos'!$C$5:$C$26,"EE.UU.",'1. Datos brutos'!$N$5:$N$26) -> 2.27 | G16: =AVERAGE('1. Datos brutos'!$N$5:$N$26) -> 2.5063636 | H16: =STDEV('1. Datos brutos'!$N$5:$N$26) -> 1.9133106
A17: 2004 | B17: =AVERAGEIF('1. Datos brutos'!$C$5:$C$26,"Eurozona core",'1. Datos brutos'!$O$5:$O$26) -> 2.5076471 | C17: =AVERAGEIF('1. Datos brutos'!$C$5:$C$26,"Bálticos",'1. Datos brutos'!$O$5:$O$26) -> 3.4666667 | D17: =AVERAGEIFS('1. Datos brutos'!$O$5:$O$26,'1. Datos brutos'!$C$5:$C$26,"Bálticos",'1. Datos brutos'!$O$5:$O$26,"<=30") -> 3.4666667 | E17: =AVERAGEIF('1. Datos brutos'!$C$5:$C$26,"Reino Unido",'1. Datos brutos'!$O$5:$O$26) -> 1.39 | F17: =AVERAGEIF('1. Datos brutos'!$C$5:$C$26,"EE.UU.",'1. Datos brutos'!$O$5:$O$26) -> 2.68 | G17: =AVERAGE('1. Datos brutos'!$O$5:$O$26) -> 2.5954545 | H17: =STDEV('1. Datos brutos'!$O$5:$O$26) -> 1.5821075
A18: 2005 | B18: =AVERAGEIF('1. Datos brutos'!$C$5:$C$26,"Eurozona core",'1. Datos brutos'!$P$5:$P$26) -> 2.4047059 | C18: =AVERAGEIF('1. Datos brutos'!$C$5:$C$26,"Bálticos",'1. Datos brutos'!$P$5:$P$26) -> 4.4966667 | D18: =AVERAGEIFS('1. Datos brutos'!$P$5:$P$26,'1. Datos brutos'!$C$5:$C$26,"Bálticos",'1. Datos brutos'!$P$5:$P$26,"<=30") -> 4.4966667 | E18: =AVERAGEIF('1. Datos brutos'!$C$5:$C$26,"Reino Unido",'1. Datos brutos'!$P$5:$P$26) -> 2.09 | F18: =AVERAGEIF('1. Datos brutos'!$C$5:$C$26,"EE.UU.",'1. Datos brutos'!$P$5:$P$26) -> 3.39 | G18: =AVERAGE('1. Datos brutos'!$P$5:$P$26) -> 2.7204545 | H18: =STDEV('1. Datos brutos'!$P$5:$P$26) -> 1.1832501
A19: 2006 | B19: =AVERAGEIF('1. Datos brutos'!$C$5:$C$26,"Eurozona core",'1. Datos brutos'!$Q$5:$Q$26) -> 2.5229412 | C19: =AVERAGEIF('1. Datos brutos'!$C$5:$C$26,"Bálticos",'1. Datos brutos'!$Q$5:$Q$26) -> 4.9066667 | D19: =AVERAGEIFS('1. Datos brutos'!$Q$5:$Q$26,'1. Datos brutos'!$C$5:$C$26,"Bálticos",'1. Datos brutos'!$Q$5:$Q$26,"<=30") -> 4.9066667 | E19: =AVERAGEIF('1. Datos brutos'!$C$5:$C$26,"Reino Unido",'1. Datos brutos'!$Q$5:$Q$26) -> 2.46 | F19: =AVERAGEIF('1. Datos brutos'!$C$5:$C$26,"EE.UU.",'1. Datos brutos'!$Q$5:$Q$26) -> 3.23 | G19: =AVERAGE('1. Datos brutos'!$Q$5:$Q$26) -> 2.8772727 | H19: =STDEV('1. Datos brutos'!$Q$5:$Q$26) -> 1.266443
